terminate called after throwing an instance of 'std::logic_error'
  what():  For condition type error!
